Workbook

Sheet Pistetaulukko
A1: XCO
A2: Sijoitus | B2: Pisteet
A3: 1 | B3: 30
A4: 2 | B4: 25
A5: 3 | B5: 21
A6: 4 | B6: 18
A7: 5 | B7: 16
A8: 6 | B8: 14
A9: 7 | B9: 12
A10: 8 | B10: 10
A11: 9 | B11: 8
A12: 10 | B12: 7
A13: 11 | B13: 6
A14: 12 | B14: 5
... A18: 16 | B18: 1
A19: Tästä eteenpäin kaikille maaliin tulleille 1 piste

Sheet DATA
A1: Laji | B1: Kilpailu | C1: Sarja | D1: Sijoitus | E1: Nimi | F1: Seura | G1: IndXCO | H1: PstXCO | I1: IndXCC | J1: PstXCC | K1: Pisteet
A2: XCO | B2: Hyvinkää XCO | C2: N-Elite | D2: 1 | E2: Mäkinen Sanna | F2: =INDEX(Taulukko25[Seura],MATCH(E2,Taulukko25[Nimi],0)) -> RSR | G2: =MATCH(D2,Pistetaulukko!A:A,0) -> 3 | H2: =INDEX(Pistetaulukko!B:B,G2) -> 30 | I2: =MATCH(D2,Pistetaulukko!D:D,0) -> #N/A | J2: =INDEX(Pistetaulukko!E:E,I2) -> #N/A | K2: =IF(Taulukko2[[#This Row],[Laji]]="XCO",Taulukko2[[#This Row],[PstXCO]],Taulukko2[[#This Row],[PstXCC]]) -> 30
A3: XCO | B3: Hyvinkää XCO | C3: N-Elite | D3: 2 | E3: Kanerva Noora | F3: =INDEX(Taulukko25[Seura],MATCH(E3,Taulukko25[Nimi],0)) -> KorsKa | G3: =MATCH(D3,Pistetaulukko!A:A,0) -> 4 | H3: =INDEX(Pistetaulukko!B:B,G3) -> 25 | I3: =MATCH(D3,Pistetaulukko!D:D,0) -> #N/A | J3: =INDEX(Pistetaulukko!E:E,I3) -> #N/A | K3: =IF(Taulukko2[[#This Row],[Laji]]="XCO",Taulukko2[[#This Row],[PstXCO]],Taulukko2[[#This Row],[PstXCC]]) -> 25
A4: XCO | B4: Hyvinkää XCO | C4: N-Elite | D4: 3 | E4: Häkkinen Hanna | F4: =INDEX(Taulukko25[Seura],MATCH(E4,Taulukko25[Nimi],0)) -> RSR | G4: =MATCH(D4,Pistetaulukko!A:A,0) -> 5 | H4: =INDEX(Pistetaulukko!B:B,G4) -> 21 | I4: =MATCH(D4,Pistetaulukko!D:D,0) -> #N/A | J4: =INDEX(Pistetaulukko!E:E,I4) -> #N/A | K4: =IF(Taulukko2[[#This Row],[Laji]]="XCO",Taulukko2[[#This Row],[PstXCO]],Taulukko2[[#This Row],[PstXCC]]) -> 21
A5: XCO | B5: Hyvinkää XCO | C5: N-Elite | D5: 4 | E5: Orvola Stella | F5: =INDEX(Taulukko25[Seura],MATCH(E5,Taulukko25[Nimi],0)) -> RMTB | G5: =MATCH(D5,Pistetaulukko!A:A,0) -> 6 | H5: =INDEX(Pistetaulukko!B:B,G5) -> 18 | I5: =MATCH(D5,Pistetaulukko!D:D,0) -> #N/A | J5: =INDEX(Pistetaulukko!E:E,I5) -> #N/A | K5: =IF(Taulukko2[[#This Row],[Laji]]="XCO",Taulukko2[[#This Row],[PstXCO]],Taulukko2[[#This Row],[PstXCC]]) -> 18
A6: XCO | B6: Hyvinkää XCO | C6: N40 | D6: 1 | E6: Pirhonen Marja | F6: =INDEX(Taulukko25[Seura],MATCH(E6,Taulukko25[Nimi],0)) -> VlkMTB | G6: =MATCH(D6,Pistetaulukko!A:A,0) -> 3 | H6: =INDEX(Pistetaulukko!B:B,G6) -> 30 | I6: =MATCH(D6,Pistetaulukko!D:D,0) -> #N/A | J6: =INDEX(Pistetaulukko!E:E,I6) -> #N/A | K6: =IF(Taulukko2[[#This Row],[Laji]]="XCO",Taulukko2[[#This Row],[PstXCO]],Taulukko2[[#This Row],[PstXCC]]) -> 30
A7: XCO | B7: Hyvinkää XCO | C7: M-Elite | D7: 1 | E7: Rantanen Aksel | F7: =INDEX(Taulukko25[Seura],MATCH(E7,Taulukko25[Nimi],0)) -> VlkMTB | G7: =MATCH(D7,Pistetaulukko!A:A,0) -> 3 | H7: =INDEX(Pistetaulukko!B:B,G7) -> 30 | I7: =MATCH(D7,Pistetaulukko!D:D,0) -> #N/A | J7: =INDEX(Pistetaulukko!E:E,I7) -> #N/A | K7: =IF(Taulukko2[[#This Row],[Laji]]="XCO",Taulukko2[[#This Row],[PstXCO]],Taulukko2[[#This Row],[PstXCC]]) -> 30
A8: XCO | B8: Hyvinkää XCO | C8: M-Elite | D8: 2 | E8: Utkin Mikhail | F8: =INDEX(Taulukko25[Seura],MATCH(E8,Taulukko25[Nimi],0)) -> Akilles | G8: =MATCH(D8,Pistetaulukko!A:A,0) -> 4 | H8: =INDEX(Pistetaulukko!B:B,G8) -> 25 | I8: =MATCH(D8,Pistetaulukko!D:D,0) -> #N/A | J8: =INDEX(Pistetaulukko!E:E,I8) -> #N/A | K8: =IF(Taulukko2[[#This Row],[Laji]]="XCO",Taulukko2[[#This Row],[PstXCO]],Taulukko2[[#This Row],[PstXCC]]) -> 25
A9: XCO | B9: Hyvinkää XCO | C9: M-Elite | D9: 3 | E9: Simonen Niklas | F9: =INDEX(Taulukko25[Seura],MATCH(E9,Taulukko25[Nimi],0)) -> TWD-Länken | G9: =MATCH(D9,Pistetaulukko!A:A,0) -> 5 | H9: =INDEX(Pistetaulukko!B:B,G9) -> 21 | I9: =MATCH(D9,Pistetaulukko!D:D,0) -> #N/A | J9: =INDEX(Pistetaulukko!E:E,I9) -> #N/A | K9: =IF(Taulukko2[[#This Row],[Laji]]="XCO",Taulukko2[[#This Row],[PstXCO]],Taulukko2[[#This Row],[PstXCC]]) -> 21
A10: XCO | B10: Hyvinkää XCO | C10: M-Elite | D10: 4 | E10: Kleemola Joona | F10: =INDEX(Taulukko25[Seura],MATCH(E10,Taulukko25[Nimi],0)) -> LaPy | G10: =MATCH(D10,Pistetaulukko!A:A,0) -> 6 | H10: =INDEX(Pistetaulukko!B:B,G10) -> 18 | I10: =MATCH(D10,Pistetaulukko!D:D,0) -> #N/A | J10: =INDEX(Pistetaulukko!E:E,I10) -> #N/A | K10: =IF(Taulukko2[[#This Row],[Laji]]="XCO",Taulukko2[[#This Row],[PstXCO]],Taulukko2[[#This Row],[PstXCC]]) -> 18
A11: XCO | B11: Hyvinkää XCO | C11: MU19 | D11: 1 | E11: Hongisto Eero | F11: =INDEX(Taulukko25[Seura],MATCH(E11,Taulukko25[Nimi],0)) -> LrPy | G11: =MATCH(D11,Pistetaulukko!A:A,0) -> 3 | H11: =INDEX(Pistetaulukko!B:B,G11) -> 30 | I11: =MATCH(D11,Pistetaulukko!D:D,0) -> #N/A | J11: =INDEX(Pistetaulukko!E:E,I11) -> #N/A | K11: =IF(Taulukko2[[#This Row],[Laji]]="XCO",Taulukko2[[#This Row],[PstXCO]],Taulukko2[[#This Row],[PstXCC]]) -> 30
A12: XCO | B12: Hyvinkää XCO | C12: MU19 | D12: 2 | E12: Kangasluoma Väinö | F12: =INDEX(Taulukko25[Seura],MATCH(E12,Taulukko25[Nimi],0)) -> Rideep | G12: =MATCH(D12,Pistetaulukko!A:A,0) -> 4 | H12: =INDEX(Pistetaulukko!B:B,G12) -> 25 | I12: =MATCH(D12,Pistetaulukko!D:D,0) -> #N/A | J12: =INDEX(Pistetaulukko!E:E,I12) -> #N/A | K12: =IF(Taulukko2[[#This Row],[Laji]]="XCO",Taulukko2[[#This Row],[PstXCO]],Taulukko2[[#This Row],[PstXCC]]) -> 25
A13: XCO | B13: Hyvinkää XCO | C13: MU19 | D13: 3 | E13: Kaapu Oiva | F13: =INDEX(Taulukko25[Seura],MATCH(E13,Taulukko25[Nimi],0)) -> VlkMTB | G13: =MATCH(D13,Pistetaulukko!A:A,0) -> 5 | H13: =INDEX(Pistetaulukko!B:B,G13) -> 21 | I13: =MATCH(D13,Pistetaulukko!D:D,0) -> #N/A | J13: =INDEX(Pistetaulukko!E:E,I13) -> #N/A | K13: =IF(Taulukko2[[#This Row],[Laji]]="XCO",Taulukko2[[#This Row],[PstXCO]],Taulukko2[[#This Row],[PstXCC]]) -> 21
... A18: XCO | B18: Hyvinkää XCO | C18: M40 | D18: 1 | E18: Hesso Johannes | F18: =INDEX(Taulukko25[Seura],MATCH(E18,Taulukko25[Nimi],0)) -> CCH | G18: =MATCH(D18,Pistetaulukko!A:A,0) -> 3 | H18: =INDEX(Pistetaulukko!B:B,G18) -> 30 | I18: =MATCH(D18,Pistetaulukko!D:D,0) -> #N/A | J18: =INDEX(Pistetaulukko!E:E,I18) -> #N/A | K18: =IF(Taulukko2[[#This Row],[Laji]]="XCO",Taulukko2[[#This Row],[PstXCO]],Taulukko2[[#This Row],[PstXCC]]) -> 30
A19: XCO | B19: Hyvinkää XCO | C19: M40 | D19: 2 | E19: Malm Mika | F19: =INDEX(Taulukko25[Seura],MATCH(E19,Taulukko25[Nimi],0)) -> TY | G19: =MATCH(D19,Pistetaulukko!A:A,0) -> 4 | H19: =INDEX(Pistetaulukko!B:B,G19) -> 25 | I19: =MATCH(D19,Pistetaulukko!D:D,0) -> #N/A | J19: =INDEX(Pistetaulukko!E:E,I19) -> #N/A | K19: =IF(Taulukko2[[#This Row],[Laji]]="XCO",Taulukko2[[#This Row],[PstXCO]],Taulukko2[[#This Row],[PstXCC]]) -> 25 | L19: =IF(A2="XCO",1,0) -> 1
A20: XCO | B20: Hyvinkää XCO | C20: M50 | D20: 1 | E20: Korpela Aki | F20: =INDEX(Taulukko25[Seura],MATCH(E20,Taulukko25[Nimi],0)) -> VlkMTB | G20: =MATCH(D20,Pistetaulukko!A:A,0) -> 3 | H20: =INDEX(Pistetaulukko!B:B,G20) -> 30 | I20: =MATCH(D20,Pistetaulukko!D:D,0) -> #N/A | J20: =INDEX(Pistetaulukko!E:E,I20) -> #N/A | K20: =IF(Taulukko2[[#This Row],[Laji]]="XCO",Taulukko2[[#This Row],[PstXCO]],Taulukko2[[#This Row],[PstXCC]]) -> 30
A21: XCO | B21: Hyvinkää XCO | C21: M50 | D21: 2 | E21: Hakala Arto | F21: =INDEX(Taulukko25[Seura],MATCH(E21,Taulukko25[Nimi],0)) -> VlkMTB | G21: =MATCH(D21,Pistetaulukko!A:A,0) -> 4 | H21: =INDEX(Pistetaulukko!B:B,G21) -> 25 | I21: =MATCH(D21,Pistetaulukko!D:D,0) -> #N/A | J21: =INDEX(Pistetaulukko!E:E,I21) -> #N/A | K21: =IF(Taulukko2[[#This Row],[Laji]]="XCO",Taulukko2[[#This Row],[PstXCO]],Taulukko2[[#This Row],[PstXCC]]) -> 25
A22: XCO | B22: Hyvinkää XCO | C22: M50 | D22: 3 | E22: Laine Mikko | F22: =INDEX(Taulukko25[Seura],MATCH(E22,Taulukko25[Nimi],0)) -> CC Ilves | G22: =MATCH(D22,Pistetaulukko!A:A,0) -> 5 | H22: =INDEX(Pistetaulukko!B:B,G22) -> 21 | I22: =MATCH(D22,Pistetaulukko!D:D,0) -> #N/A | J22: =INDEX(Pistetaulukko!E:E,I22) -> #N/A | K22: =IF(Taulukko2[[#This Row],[Laji]]="XCO",Taulukko2[[#This Row],[PstXCO]],Taulukko2[[#This Row],[PstXCC]]) -> 21
A23: XCO | B23: Hyvinkää XCO | C23: M50 | D23: 4 | E23: Vainio Panu | F23: =INDEX(Taulukko25[Seura],MATCH(E23,Taulukko25[Nimi],0)) -> CCH | G23: =MATCH(D23,Pistetaulukko!A:A,0) -> 6 | H23: =INDEX(Pistetaulukko!B:B,G23) -> 18 | I23: =MATCH(D23,Pistetaulukko!D:D,0) -> #N/A | J23: =INDEX(Pistetaulukko!E:E,I23) -> #N/A | K23: =IF(Taulukko2[[#This Row],[Laji]]="XCO",Taulukko2[[#This Row],[PstXCO]],Taulukko2[[#This Row],[PstXCC]]) -> 18
A24: XCO | B24: Cycli-XCO | C24: N-Elite | D24: 1 | E24: Alusniemi Sini | F24: =INDEX(Taulukko25[Seura],MATCH(E24,Taulukko25[Nimi],0)) -> JYPS | G24: =MATCH(D24,Pistetaulukko!A:A,0) -> 3 | H24: =INDEX(Pistetaulukko!B:B,G24) -> 30 | I24: =MATCH(D24,Pistetaulukko!D:D,0) -> #N/A | J24: =INDEX(Pistetaulukko!E:E,I24) -> #N/A | K24: =IF(Taulukko2[[#This Row],[Laji]]="XCO",Taulukko2[[#This Row],[PstXCO]],Taulukko2[[#This Row],[PstXCC]]) -> 30
A25: XCO | B25: Cycli-XCO | C25: N-Elite | D25: 2 | E25: Kanerva Noora | F25: =INDEX(Taulukko25[Seura],MATCH(E25,Taulukko25[Nimi],0)) -> KorsKa | G25: =MATCH(D25,Pistetaulukko!A:A,0) -> 4 | H25: =INDEX(Pistetaulukko!B:B,G25) -> 25 | I25: =MATCH(D25,Pistetaulukko!D:D,0) -> #N/A | J25: =INDEX(Pistetaulukko!E:E,I25) -> #N/A | K25: =IF(Taulukko2[[#This Row],[Laji]]="XCO",Taulukko2[[#This Row],[PstXCO]],Taulukko2[[#This Row],[PstXCC]]) -> 25
A26: XCO | B26: Cycli-XCO | C26: N-Elite | D26: 3 | E26: Teronen Anni | F26: =INDEX(Taulukko25[Seura],MATCH(E26,Taulukko25[Nimi],0)) -> ProMTB | G26: =MATCH(D26,Pistetaulukko!A:A,0) -> 5 | H26: =INDEX(Pistetaulukko!B:B,G26) -> 21 | I26: =MATCH(D26,Pistetaulukko!D:D,0) -> #N/A | J26: =INDEX(Pistetaulukko!E:E,I26) -> #N/A | K26: =IF(Taulukko2[[#This Row],[Laji]]="XCO",Taulukko2[[#This Row],[PstXCO]],Taulukko2[[#This Row],[PstXCC]]) -> 21
A27: XCO | B27: Cycli-XCO | C27: N-Elite | D27: 4 | E27: Kansikas Sofia | F27: =INDEX(Taulukko25[Seura],MATCH(E27,Taulukko25[Nimi],0)) -> CCH | G27: =MATCH(D27,Pistetaulukko!A:A,0) -> 6 | H27: =INDEX(Pistetaulukko!B:B,G27) -> 18 | I27: =MATCH(D27,Pistetaulukko!D:D,0) -> #N/A | J27: =INDEX(Pistetaulukko!E:E,I27) -> #N/A | K27: =IF(Taulukko2[[#This Row],[Laji]]="XCO",Taulukko2[[#This Row],[PstXCO]],Taulukko2[[#This Row],[PstXCC]]) -> 18
A28: XCO | B28: Cycli-XCO | C28: N40 | D28: 1 | E28: Mielonen Noora | F28: =INDEX(Taulukko25[Seura],MATCH(E28,Taulukko25[Nimi],0)) -> Rideep | G28: =MATCH(D28,Pistetaulukko!A:A,0) -> 3 | H28: =INDEX(Pistetaulukko!B:B,G28) -> 30 | I28: =MATCH(D28,Pistetaulukko!D:D,0) -> #N/A | J28: =INDEX(Pistetaulukko!E:E,I28) -> #N/A | K28: =IF(Taulukko2[[#This Row],[Laji]]="XCO",Taulukko2[[#This Row],[PstXCO]],Taulukko2[[#This Row],[PstXCC]]) -> 30
A29: XCO | B29: Cycli-XCO | C29: N40 | D29: 2 | E29: Hernetkoski Hanna | F29: =INDEX(Taulukko25[Seura],MATCH(E29,Taulukko25[Nimi],0)) -> RaKe | G29: =MATCH(D29,Pistetaulukko!A:A,0) -> 4 | H29: =INDEX(Pistetaulukko!B:B,G29) -> 25 | I29: =MATCH(D29,Pistetaulukko!D:D,0) -> #N/A | J29: =INDEX(Pistetaulukko!E:E,I29) -> #N/A | K29: =IF(Taulukko2[[#This Row],[Laji]]="XCO",Taulukko2[[#This Row],[PstXCO]],Taulukko2[[#This Row],[PstXCC]]) -> 25
A30: XCO | B30: Cycli-XCO | C30: NU19 | D30: 1 | E30: Pietilä Anni | F30: =INDEX(Taulukko25[Seura],MATCH(E30,Taulukko25[Nimi],0)) -> OTC | G30: =MATCH(D30,Pistetaulukko!A:A,0) -> 3 | H30: =INDEX(Pistetaulukko!B:B,G30) -> 30 | I30: =MATCH(D30,Pistetaulukko!D:D,0) -> #N/A | J30: =INDEX(Pistetaulukko!E:E,I30) -> #N/A | K30: =IF(Taulukko2[[#This Row],[Laji]]="XCO",Taulukko2[[#This Row],[PstXCO]],Taulukko2[[#This Row],[PstXCC]]) -> 30
A31: XCO | B31: Cycli-XCO | C31: M-Elite | D31: 1 | E31: Savaste Joni | F31: =INDEX(Taulukko25[Seura],MATCH(E31,Taulukko25[Nimi],0)) -> RaKe / Team Evoc | G31: =MATCH(D31,Pistetaulukko!A:A,0) -> 3 | H31: =INDEX(Pistetaulukko!B:B,G31) -> 30 | I31: =MATCH(D31,Pistetaulukko!D:D,0) -> #N/A | J31: =INDEX(Pistetaulukko!E:E,I31) -> #N/A | K31: =IF(Taulukko2[[#This Row],[Laji]]="XCO",Taulukko2[[#This Row],[PstXCO]],Taulukko2[[#This Row],[PstXCC]]) -> 30
... A200: XCO | B200: 6. XCO-SM | C200: NU19 | D200: 4 | E200: Koivula Ella | F200: =INDEX(Taulukko25[Seura],MATCH(E200,Taulukko25[Nimi],0)) -> KorsKa | G200: =MATCH(D200,Pistetaulukko!A:A,0) -> 6 | H200: =INDEX(Pistetaulukko!B:B,G200) -> 18 | I200: =MATCH(D200,Pistetaulukko!D:D,0) -> #N/A | J200: =INDEX(Pistetaulukko!E:E,I200) -> #N/A | K200: =IF(Taulukko2[[#This Row],[Laji]]="XCO",Taulukko2[[#This Row],[PstXCO]],Taulukko2[[#This Row],[PstXCC]]) -> 18
K895: n e n

Sheet Seurat
A1: Nimi | B1: Seura | C1: Sarake1
A2: Aittakorpi Ante | B2: RaKe
A3: Alaluusua Rene | B3: TVC
A4: Alhonen Sofia | B4: IK-32
A5: Arminen Anton | B5: KorsKa
A6: Aspholm Finley | B6: Akilles
A7: Astikainen Oskari | B7: LrPy
A8: Autio Elias | B8: OTC
A9: Berg Kevin | B9: Ei SP jäsenseura
A10: Bloigo Mattias | B10: Ei SP jäsenseura
A11: Blomback Saga | B11: JurU
A12: Borremans Kasper | B12: RaKe
A13: Borremans Lotte | B13: RaKe
... A16: Eklund Oliver | B16: Ei SP jäsenseura
A17: Ekman Iris | B17: Ei SP jäsenseura | C17: MTBCF ry
A18: Enojärvi Aatu | B18: TCC
A19: Eskelinen Aatos | B19: RaKe
A20: Eskelinen Elias | B20: RaKe
A21: Eskelinen Hilla | B21: RaKe
A22: Gillett Fionn | B22: Ei SP jäsenseura | C22: Ei seuraa
A23: Golubkova Varvara | B23: UP
A24: Granberg Isac | B24: GIF
A25: Granberg Jeremia | B25: GIF
A26: Haataja Vili | B26: OPP
A27: Hakala Mari | B27: UP
A28: Halminen Iiro | B28: HyPy
A29: Harakka Frans | B29: RaKe
A30: Hassinen Noora | B30: RaKe
A31: Hassinen Sonja | B31: RaKe
A32: Heikkinen Eeli | B32: JäPy
A33: Heikkinen Iiris | B33: GIF
A34: Heikkinen Inari | B34: OTC
A35: Heikkinen Vilho | B35: JäPy
A36: Heimonen Eemeli | B36: Ei SP jäsenseura | C36: Iivari mty
A37: Heimonen Elsa | B37: Ei SP jäsenseura | C37: Iivari mty
A38: Heinänen Eino | B38: RaKe
A39: Heinänen Henrik | B39: RaKe
A40: Heiskanen Tuomo | B40: Ei SP jäsenseura | C40: Ei seuraa
A41: Helander Niklas | B41: HHCMB
A42: Helenius Olli | B42: KorsKa
...

Sheet Suttu

Sheet Pivot 2024
A3: Summa / Pisteet | C3: Kilpailu
A4: Sarja | B4: Nimi | C4: Hyvinkää XCO | D4: Cycli-XCO | E4: 3.Köykäri XCC | F4: 4.Köykäri XCO | G4: 5. XCC-SM | H4: 6. XCO-SM | I4: 7. Korsisaari | J4: 8. Rovaniemi | K4: Kaikki yhteensä
A5: M-Elite
B6: Utkin Mikhail | C6: 17 | D6: 15 | E6: 10 | F6: 20 | G6: 8 | I6: 20 | K6: 90
B7: Rantanen Aksel | C7: 20 | D7: 17 | G7: 10 | H7: 20 | K7: 67
B8: Lehtinen Sakari | H8: 15 | I8: 17 | K8: 32
B9: Savaste Joni | D9: 20 | J9: 10 | K9: 30
B10: Tuppurainen Ville | G10: 6 | H10: 17 | K10: 23
B11: Vainio Mikko | E11: 6 | F11: 13 | K11: 19
B12: Teppo Petja | F12: 17 | K12: 17
B13: Lipponen Aatu | F13: 15 | K13: 15
B14: Härginen Dani | I14: 15 | K14: 15
B15: Simonen Niklas | C15: 15 | K15: 15
B16: Terho Niko | D16: 13 | K16: 13
B17: Pelkonen Ville | I17: 13 | K17: 13
B18: Kleemola Joona | C18: 13 | K18: 13
B19: Sairanen Iiro | D19: 11 | K19: 11
B20: Heikkilä Niko | J20: 8 | K20: 8
B21: Karsikas Ilkka | E21: 8 | K21: 8
B22: Halme Sasu | J22: 6 | K22: 6
B23: Väänänen Heikki | G23: 5 | K23: 5
B24: Havana Juha | J24: 5 | K24: 5
B25: Terävä Simo | J25: 4 | K25: 4
B26: Halme Samuel | G26: 4 | K26: 4
B27: Ahtosalo Matias | G27: 3 | K27: 3
B28: Hongisto Eero | J28: 3 | K28: 3
A29: N-Elite
B30: Alusniemi Sini | D30: 20 | F30: 20 | H30: 20 | I30: 20 | K30: 80
B31: Kanerva Noora | C31: 17 | D31: 17 | H31: 17 | K31: 51
B32: Tapio Anni | E32: 10 | F32: 17 | G32: 4 | H32: 11 | J32: 8 | K32: 50
B33: Havana Henna-Mari | G33: 10 | H33: 13 | J33: 10 | K33: 33
B34: Häkkinen Hanna | C34: 15 | H34: 15 | K34: 30
B35: Mäkinen Sanna | C35: 20 | K35: 20
B36: Orvola Stella | C36: 13 | J36: 6 | K36: 19
B37: Teronen Anni | D37: 15 | K37: 15
B38: Kansikas Sofia | D38: 13 | K38: 13
B39: Saarela Ruska | G39: 8 | K39: 8
B40: Snäll Astrid | G40: 6 | K40: 6
B41: Johansson Idamari | G41: 5 | K41: 5
A42: MU19
...

Sheet XCO-CUP Pistetilanne
A1: XCO-CUP 2024
A2: Suomen Pyöräily
A3: Palaute: vesa.laapas@pyoraily.fi
A4: XCO-CUP internet-sivusto
B6: Kilpailut
A7: 1 | B7: Hyvinkää XCO
A8: 2 | B8: Cycli XCO
A9: 3 | B9: Kokkola MTB XCC
A10: 4 | B10: Kokkola MTB XCO
A11: 5 | B11: XCC-SM
A12: 6 | B12: XCO-SM
A13: 7 | B13: Korsisaari XCO
A14: 8 | B14: Rovaniemi XCC
A17: Sarja | B17: Nimi | D17: 1 | E17: 2 | F17: 3 | G17: 4 | H17: 5 | I17: 6 | J17: Yht.
A18: M-Elite
B19: Utkin Mikhail | C19: =INDEX(Taulukko25[Seura],MATCH(B19,Taulukko25[Nimi],0)) -> Akilles | D19: 17 | E19: 15 | F19: 10 | G19: 20 | H19: 8 | J19: 70
B20: Rantanen Aksel | C20: =INDEX(Taulukko25[Seura],MATCH(B20,Taulukko25[Nimi],0)) -> VlkMTB | D20: 20 | E20: 17 | H20: 10 | I20: 20 | J20: 67
B21: Tuppurainen Ville | C21: =INDEX(Taulukko25[Seura],MATCH(B21,Taulukko25[Nimi],0)) -> JYPS | H21: 6 | I21: 17 | J21: 23
B22: Savaste Joni | C22: =INDEX(Taulukko25[Seura],MATCH(B22,Taulukko25[Nimi],0)) -> RaKe / Team Evoc | E22: 20 | J22: 20
B23: Vainio Mikko | C23: =INDEX(Taulukko25[Seura],MATCH(B23,Taulukko25[Nimi],0)) -> CC Ilves | F23: 6 | G23: 13 | J23: 19
B24: Teppo Petja | C24: =INDEX(Taulukko25[Seura],MATCH(B24,Taulukko25[Nimi],0)) -> GIF | G24: 17 | J24: 17
B25: Simonen Niklas | C25: =INDEX(Taulukko25[Seura],MATCH(B25,Taulukko25[Nimi],0)) -> TWD-Länken | D25: 15 | J25: 15
B26: Lipponen Aatu | C26: =INDEX(Taulukko25[Seura],MATCH(B26,Taulukko25[Nimi],0)) -> OTC | G26: 15 | J26: 15
B27: Lehtinen Sakari | C27: =INDEX(Taulukko25[Seura],MATCH(B27,Taulukko25[Nimi],0)) -> HyPy | I27: 15 | J27: 15
B28: Terho Niko | C28: =INDEX(Taulukko25[Seura],MATCH(B28,Taulukko25[Nimi],0)) -> TVC | E28: 13 | J28: 13
B29: Kleemola Joona | C29: =INDEX(Taulukko25[Seura],MATCH(B29,Taulukko25[Nimi],0)) -> LaPy | D29: 13 | J29: 13
B30: Sairanen Iiro | C30: =INDEX(Taulukko25[Seura],MATCH(B30,Taulukko25[Nimi],0)) -> IU | E30: 11 | J30: 11
B31: Karsikas Ilkka | C31: =INDEX(Taulukko25[Seura],MATCH(B31,Taulukko25[Nimi],0)) -> PyöRi | F31: 8 | J31: 8
B32: Väänänen Heikki | C32: =INDEX(Taulukko25[Seura],MATCH(B32,Taulukko25[Nimi],0)) -> VlkMTB | H32: 5 | J32: 5
B33: Halme Samuel | C33: =INDEX(Taulukko25[Seura],MATCH(B33,Taulukko25[Nimi],0)) -> JYPS | H33: 4 | J33: 4
B34: Ahtosalo Matias | C34: =INDEX(Taulukko25[Seura],MATCH(B34,Taulukko25[Nimi],0)) -> KorsKa | H34: 3 | J34: 3
A35: N-Elite
B36: Alusniemi Sini | C36: =INDEX(Taulukko25[Seura],MATCH(B36,Taulukko25[Nimi],0)) -> JYPS | E36: 20 | G36: 20 | I36: 20 | J36: 60
B37: Kanerva Noora | C37: =INDEX(Taulukko25[Seura],MATCH(B37,Taulukko25[Nimi],0)) -> KorsKa | D37: 17 | E37: 17 | I37: 17 | J37: 51
B38: Tapio Anni | C38: =INDEX(Taulukko25[Seura],MATCH(B38,Taulukko25[Nimi],0)) -> OP-P | F38: 10 | G38: 17 | H38: 4 | I38: 11 | J38: 42
B39: Häkkinen Hanna | C39: =INDEX(Taulukko25[Seura],MATCH(B39,Taulukko25[Nimi],0)) -> RSR | D39: 15 | I39: 15 | J39: 30
B40: Havana Henna-Mari | C40: =INDEX(Taulukko25[Seura],MATCH(B40,Taulukko25[Nimi],0)) -> OTC | H40: 10 | I40: 13 | J40: 23
B41: Mäkinen Sanna | C41: =INDEX(Taulukko25[Seura],MATCH(B41,Taulukko25[Nimi],0)) -> RSR | D41: 20 | J41: 20
B42: Teronen Anni | C42: =INDEX(Taulukko25[Seura],MATCH(B42,Taulukko25[Nimi],0)) -> ProMTB | E42: 15 | J42: 15
B43: Orvola Stella | C43: =INDEX(Taulukko25[Seura],MATCH(B43,Taulukko25[Nimi],0)) -> RMTB | D43: 13 | J43: 13
...

Sheet Seura Pivot
A3: Riviotsikot | B3: Summa / Pisteet
A4: VlkMTB | B4: 275
A5: KorsKa | B5: 212
A6: OTC | B6: 199
A7: HyPy | B7: 162
A8: Rideep | B8: 134
A9: JYPS | B9: 111
A10: ProMTB | B10: 110
A11: CCH | B11: 109
A12: Larsmo IF | B12: 107
A13: Akilles | B13: 105
A14: OP-P | B14: 93
A15: IU | B15: 88
... A22: RaKe | B22: 46
A23: 0 | B23: 30
A24: RaKe / Team Evoc | B24: 30
A25: TVC | B25: 27
A26: Ei SP jäsenseura | B26: 25
A27: VeloSaimaa | B27: 25
A28: JäPy | B28: 25
A29: LaPy | B29: 21
A30: KangKi | B30: 20
A31: PVCC | B31: 20
A32: TWD-Länken | B32: 15
A33: GIF / Prorog MTB Team | B33: 15
A34: PoTa | B34: 12
A35: IK-32 | B35: 11
... A39: Kaikki yhteensä | B39: 2430

Sheet Taul3
A2: Rata | B2: ISM aika-ajo rata | C2: M-16 | D2: 1 | E2: Källberg Ivar | F2: Kraft
A3: Rata | B3: ISM aika-ajo rata | C3: M-16 | D3: 2 | E3: Oilinki Joona | F3: CCH
A4: Rata | B4: ISM aika-ajo rata | C4: M-16 | D4: 3 | E4: Vuorio René | F4: TuUL
A5: Rata | B5: ISM aika-ajo rata | C5: M-16 | D5: 4 | E5: Lahtinen Lauri | F5: KoiI
A6: Rata | B6: ISM aika-ajo rata | C6: M-16 | D6: 5 | E6: Yrjänäinen Eelis | F6: TuUL
A7: Rata | B7: ISM aika-ajo rata | C7: M-16 | D7: 6 | E7: Kuusisto Sebastian | F7: PoTa
A8: Rata | B8: ISM aika-ajo rata | C8: M-16 | D8: 7 | E8: Suikki Tuomas | F8: TuUL
A9: Rata | B9: ISM aika-ajo rata | C9: M-16 | D9: 8 | E9: Holopainen Arttu | F9: KoiI
A10: Rata | B10: ISM aika-ajo rata | C10: M-16 | D10: 9 | E10: Metsomäki Olli | F10: CCH
A11: Rata | B11: ISM aika-ajo rata | C11: M-10 | D11: 1 | E11: Peltonen Bruno | F11: PoTa
A12: Rata | B12: ISM aika-ajo rata | C12: M-10 | D12: 2 | E12: Holopainen Alex | F12: KoiI
A13: Rata | B13: ISM aika-ajo rata | C13: M-10 | D13: 3 | E13: Träskelin Pontus | F13: TVC
... A67: Rata | B67: ISM takaa-ajo | C67: N-16 | D67: 3 | E67: Terho Jessica | F67: TVC
A68: Maantie | B68: ISM aika-ajo | C68: M-10 | D68: 1 | E68: Väyrynen Viljami
A69: Maantie | B69: ISM aika-ajo | C69: M-10 | D69: 2 | E69: Malm Leo
A70: Maantie | B70: ISM aika-ajo | C70: M-10 | D70: 3 | E70: Lahtinen Reima
A71: Maantie | B71: ISM aika-ajo | C71: M-10 | D71: 4 | E71: Häikiö Aaro
A72: Maantie | B72: ISM aika-ajo | C72: M-10 | D72: 5 | E72: Riutta Lenni
A73: Maantie | B73: ISM aika-ajo | C73: M-10 | D73: 6 | E73: Pietilä Eddi
A74: Maantie | B74: ISM aika-ajo | C74: M-10 | D74: 7 | E74: Vasankari Eeli
A75: Maantie | B75: ISM aika-ajo | C75: M-10 | D75: 8 | E75: Peltonen Bruno
A76: Maantie | B76: ISM aika-ajo | C76: M-10 | D76: 9 | E76: Similä Eeli
A77: Maantie | B77: ISM aika-ajo | C77: M-10 | D77: 10 | E77: Samppala Aapo
A78: Maantie | B78: ISM aika-ajo | C78: M-10 | D78: 11 | E78: Nikkilä Elias
A79: Maantie | B79: ISM aika-ajo | C79: M-10 | D79: 12 | E79: Loukko Iivari
... A185: Maantie | B185: ISM maantie | C185: M-16 | D185: 9 | E185: Rose Antoni

Sheet Mitalistit
A1: Hei. Tässä mitalit Suomen Pyöräilyn Kultainen Kampi -cupissa menestyneille junioreille.
A2: Valitettavasti nuorisojaostolla ei ole resursseja järjestää valtakunnallista
A3: palkintojen jakoa, mutta toivomme että jaatte mitalit sopivan juhlallisessa seuran yhteisessä tilaisuudessa.
A4: Onnittelut menestyneille ja kiitos seurallenne pyöräilyn eteen tehdystä juniorityöstä.
A5: Suomen Pyöräily, Nuorisojaosto. / Vesa Laapas vesa.laapas@pyoraily.fi
A7: Laji | B7: Sarja | C7: Sija | D7: Nimi | E7: Seura
A8: Maasto | B8: MU11 | C8: 1 | D8: Pietilä Eddi | E8: GIF
A9: Maasto | B9: MU11 | C9: 2 | D9: Kirssi Antto | E9: KoPy
A10: Maasto | B10: MU11 | C10: 3 | D10: Henriksson Tatu | E10: RaKe
A11: Maasto | B11: MU13 | C11: 1 | D11: Granberg Jeremia | E11: GIF
A12: Maasto | B12: MU13 | C12: 2 | D12: Lehtonen Veeti | E12: TVC
A13: Maasto | B13: MU13 | C13: 3 | D13: Malinen Arttu | E13: JoensPy
A14: Maasto | B14: MU15 | C14: 1 | D14: Malinen Konsta | E14: JoensPy
A15: Maasto | B15: MU15 | C15: 2 | D15: Nieminen Kasperi | E15: IU
A16: Maasto | B16: MU15 | C16: 3 | D16: Kornijenko Kuzma | E16: CCH
A17: Maasto | B17: MU17 | C17: 1 | D17: Kangasluoma Väinö | E17: Rideep
A18: Maasto | B18: MU17 | C18: 2 | D18: Lampila Veli | E18: ProMTB
A19: Maasto | B19: MU17 | C19: 3 | D19: Terho Niko | E19: TVC
... A92: CX | B92: NU17 | C92: 1 | D92: Kajasoja Olivia | E92: Akilles

Sheet Osallistumiset CUP
A1: Sarja | B1: Nimi
A2: N40 | B2: Orvola Sari | J2: KokonaisCup
B3: Pirhonen Marja | H3: =IF(D3>0,1,0) -> 0 | I3: =IF(E3>0,1,0) -> 0 | J3: =SUM(G3:I3) -> 0
B4: Mielonen Noora | H4: =IF(D4>0,1,0) -> 0 | I4: =IF(E4>0,1,0) -> 0 | J4: =SUM(G4:I4) -> 0
B5: Perälä Suvi | H5: =IF(D5>0,1,0) -> 0 | I5: =IF(E5>0,1,0) -> 0 | J5: =SUM(G5:I5) -> 0
B6: Hernetkoski Hanna | H6: =IF(D6>0,1,0) -> 0 | I6: =IF(E6>0,1,0) -> 0 | J6: =SUM(G6:I6) -> 0
B7: Kaarjärv Maris | H7: =IF(D7>0,1,0) -> 0 | I7: =IF(E7>0,1,0) -> 0 | J7: =SUM(G7:I7) -> 0
B8: Eskelinen Annika | H8: =IF(D8>0,1,0) -> 0 | I8: =IF(E8>0,1,0) -> 0 | J8: =SUM(G8:I8) -> 0
B9: Rusanen Riikka | H9: =IF(D9>0,1,0) -> 0 | I9: =IF(E9>0,1,0) -> 0 | J9: =SUM(G9:I9) -> 0
A10: N40 Summa | H10: =IF(D10>0,1,0) -> 0 | I10: =IF(E10>0,1,0) -> 0 | J10: =SUM(G10:I10) -> 0
A11: NU19 | B11: Koivula Ella | H11: =IF(D11>0,1,0) -> 0 | I11: =IF(E11>0,1,0) -> 0 | J11: =SUM(G11:I11) -> 0
B12: Teronen Anni | H12: =IF(D12>0,1,0) -> 0 | I12: =IF(E12>0,1,0) -> 0 | J12: =SUM(G12:I12) -> 0
B13: Orvola Stella | H13: =IF(D13>0,1,0) -> 0 | I13: =IF(E13>0,1,0) -> 0 | J13: =SUM(G13:I13) -> 0
B14: Pietilä Anni | H14: =IF(D14>0,1,0) -> 0 | I14: =IF(E14>0,1,0) -> 0 | J14: =SUM(G14:I14) -> 0
B15: Kaarjärv Mairit | H15: =IF(D15>0,1,0) -> 0 | I15: =IF(E15>0,1,0) -> 0 | J15: =SUM(G15:I15) -> 0
B16: Kapanen Elisabet | H16: =IF(D16>0,1,0) -> 0 | I16: =IF(E16>0,1,0) -> 0 | J16: =SUM(G16:I16) -> 0
B17: Jordan Ellen | H17: =IF(D17>0,1,0) -> 0 | I17: =IF(E17>0,1,0) -> 0 | J17: =SUM(G17:I17) -> 0
A18: NU19 Summa | H18: =IF(D18>0,1,0) -> 0 | I18: =IF(E18>0,1,0) -> 0 | J18: =SUM(G18:I18) -> 0
A19: N-Elite | B19: Teronen Anni | H19: =IF(D19>0,1,0) -> 0 | I19: =IF(E19>0,1,0) -> 0 | J19: =SUM(G19:I19) -> 0
B20: Orvola Stella | H20: =IF(D20>0,1,0) -> 0 | I20: =IF(E20>0,1,0) -> 0 | J20: =SUM(G20:I20) -> 0
B21: Tapio Anni | H21: =IF(D21>0,1,0) -> 0 | I21: =IF(E21>0,1,0) -> 0 | J21: =SUM(G21:I21) -> 0
B22: Kanerva Noora | H22: =IF(D22>0,1,0) -> 0 | I22: =IF(E22>0,1,0) -> 0 | J22: =SUM(G22:I22) -> 0
B23: Kansikas Sofia | H23: =IF(D23>0,1,0) -> 0 | I23: =IF(E23>0,1,0) -> 0 | J23: =SUM(G23:I23) -> 0
B24: Alusniemi Sini | H24: =IF(D24>0,1,0) -> 0 | I24: =IF(E24>0,1,0) -> 0 | J24: =SUM(G24:I24) -> 0
B25: Mäkinen Sanna | H25: =IF(D25>0,1,0) -> 0 | I25: =IF(E25>0,1,0) -> 0 | J25: =SUM(G25:I25) -> 0
B26: Häkkinen Hanna | H26: =IF(D26>0,1,0) -> 0 | I26: =IF(E26>0,1,0) -> 0 | J26: =SUM(G26:I26) -> 0
B27: Havana Henna-Mari | H27: =IF(D27>0,1,0) -> 0 | I27: =IF(E27>0,1,0) -> 0 | J27: =SUM(G27:I27) -> 0
B28: Saarela Ruska | H28: =IF(D28>0,1,0) -> 0 | I28: =IF(E28>0,1,0) -> 0 | J28: =SUM(G28:I28) -> 0
B29: Snäll Astrid | H29: =IF(D29>0,1,0) -> 0 | I29: =IF(E29>0,1,0) -> 0 | J29: =SUM(G29:I29) -> 0
B30: Johansson Idamari | H30: =IF(D30>0,1,0) -> 0 | I30: =IF(E30>0,1,0) -> 0 | J30: =SUM(G30:I30) -> 0
A31: N-Elite Summa | H31: =IF(D31>0,1,0) -> 0 | I31: =IF(E31>0,1,0) -> 0 | J31: =SUM(G31:I31) -> 0
A32: M-Elite | B32: Hongisto Eero | H32: =IF(D32>0,1,0) -> 0 | I32: =IF(E32>0,1,0) -> 0 | J32: =SUM(G32:I32) -> 0
B33: Teppo Petja | H33: =IF(D33>0,1,0) -> 0 | I33: =IF(E33>0,1,0) -> 0 | J33: =SUM(G33:I33) -> 0
B34: Terho Niko | H34: =IF(D34>0,1,0) -> 0 | I34: =IF(E34>0,1,0) -> 0 | J34: =SUM(G34:I34) -> 0
B35: Heikkilä Niko | H35: =IF(D35>0,1,0) -> 0 | I35: =IF(E35>0,1,0) -> 0 | J35: =SUM(G35:I35) -> 0
B36: Lehtinen Sakari | H36: =IF(D36>0,1,0) -> 0 | I36: =IF(E36>0,1,0) -> 0 | J36: =SUM(G36:I36) -> 0
B37: Rantanen Aksel | H37: =IF(D37>0,1,0) -> 0 | I37: =IF(E37>0,1,0) -> 0 | J37: =SUM(G37:I37) -> 0
B38: Simonen Niklas | H38: =IF(D38>0,1,0) -> 0 | I38: =IF(E38>0,1,0) -> 0 | J38: =SUM(G38:I38) -> 0
B39: Sairanen Iiro | H39: =IF(D39>0,1,0) -> 0 | I39: =IF(E39>0,1,0) -> 0 | J39: =SUM(G39:I39) -> 0
B40: Väänänen Heikki | H40: =IF(D40>0,1,0) -> 0 | I40: =IF(E40>0,1,0) -> 0 | J40: =SUM(G40:I40) -> 0
...

Sheet Ohjeet
A1: 1. Kopioi tuloksista tiedot DATA taulukkoon. Katso mallia edellisistä. Nimet muodossa Sukunimi + Etunimi
A2: 2. Päivitä Pivot-taulukko
A3: 3. Kopioi Pivot taulukon tiedot haluttuun cup-taulukkoon. Suodata pivot siten että näkyvissä on sen cupin pistett jotka haluat kopioida.
A4: 4. Lisää Kilpailu ja upota siihen tuloslinkki ajetut kilpailut kohtaan pistetaulukon alkuun.
A5: 5. Lisää tyhjät rivit sarjojen väleihin.
A6: 6. Lisää uudet ajajat Seurat sivulle. Seura haetaan automaattisesti taulukkoon. JOs seuraa ei löydy taulukosta, ruutuun tulee 0 tai #puuttuu
A8: Tulosta *.pdf.
A9: Nimeäminen:
A10: KK-MaantieCUP
A11: KK-MaastoCUP
A12: KK-KokonaisCUP
A16: Mitallikuvake lopullisiin tuloksiin
... A27: Esimerkki:
A28: Orvola Sari | B28: =INDEX(Taulukko25[Seura],MATCH(A28,Taulukko25[Nimi],0)) -> RMTB
